{"trial_id": "00", "hyperparameters": {"space": [{"class_name": "Int", "config": {"name": "units_1", "default": null, "conditions": [], "min_value": 64, "max_value": 256, "step": 32, "sampling": "linear"}}, {"class_name": "Int", "config": {"name": "units_2", "default": null, "conditions": [], "min_value": 32, "max_value": 128, "step": 16, "sampling": "linear"}}, {"class_name": "Int", "config": {"name": "units_3", "default": null, "conditions": [], "min_value": 16, "max_value": 64, "step": 16, "sampling": "linear"}}, {"class_name": "Float", "config": {"name": "dropout", "default": 0.1, "conditions": [], "min_value": 0.1, "max_value": 0.4, "step": 0.1, "sampling": "linear"}}, {"class_name": "Choice", "config": {"name": "optimizer", "default": "adam", "conditions": [], "values": ["adam", "rmsprop"], "ordered": false}}], "values": {"units_1": 224, "units_2": 112, "units_3": 32, "dropout": 0.1, "optimizer": "adam"}}, "metrics": {"metrics": {}}, "score": null, "best_step": 0, "status": "FAILED", "message": "Traceback (most recent call last):\n  File \"/Users/riccardo/anaconda3/lib/python3.11/site-packages/keras_tuner/src/engine/base_tuner.py\", line 274, in _try_run_and_update_trial\n    self._run_and_update_trial(trial, *fit_args, **fit_kwargs)\n  File \"/Users/riccardo/anaconda3/lib/python3.11/site-packages/keras_tuner/src/engine/base_tuner.py\", line 239, in _run_and_update_trial\n    results = self.run_trial(trial, *fit_args, **fit_kwargs)\n              ^^^^^^^^^^^^^^^^^^^^^^^^^^^^^^^^^^^^^^^^^^^^^^\n  File \"/Users/riccardo/anaconda3/lib/python3.11/site-packages/keras_tuner/src/engine/tuner.py\", line 314, in run_trial\n    obj_value = self._build_and_fit_model(trial, *args, **copied_kwargs)\n                ^^^^^^^^^^^^^^^^^^^^^^^^^^^^^^^^^^^^^^^^^^^^^^^^^^^^^^^^\n  File \"/Users/riccardo/anaconda3/lib/python3.11/site-packages/keras_tuner/src/engine/tuner.py\", line 233, in _build_and_fit_model\n    results = self.hypermodel.fit(hp, model, *args, **kwargs)\n              ^^^^^^^^^^^^^^^^^^^^^^^^^^^^^^^^^^^^^^^^^^^^^^^\n  File \"/Users/riccardo/anaconda3/lib/python3.11/site-packages/keras_tuner/src/engine/hypermodel.py\", line 149, in fit\n    return model.fit(*args, **kwargs)\n           ^^^^^^^^^^^^^^^^^^^^^^^^^^\n  File \"/Users/riccardo/anaconda3/lib/python3.11/site-packages/keras/src/utils/traceback_utils.py\", line 122, in error_handler\n    raise e.with_traceback(filtered_tb) from None\n  File \"/Users/riccardo/anaconda3/lib/python3.11/site-packages/keras_tuner/src/engine/tuner_utils.py\", line 76, in on_epoch_end\n    self._save_model()\n  File \"/Users/riccardo/anaconda3/lib/python3.11/site-packages/keras_tuner/src/engine/tuner_utils.py\", line 86, in _save_model\n    self.model.save_weights(write_filepath)\n  File \"/Users/riccardo/anaconda3/lib/python3.11/site-packages/h5py/_hl/files.py\", line 562, in __init__\n    fid = make_fid(name, mode, userblock_size, fapl, fcpl, swmr=swmr)\n          ^^^^^^^^^^^^^^^^^^^^^^^^^^^^^^^^^^^^^^^^^^^^^^^^^^^^^^^^^^^\n  File \"/Users/riccardo/anaconda3/lib/python3.11/site-packages/h5py/_hl/files.py\", line 241, in make_fid\n    fid = h5f.create(name, h5f.ACC_TRUNC, fapl=fapl, fcpl=fcpl)\n          ^^^^^^^^^^^^^^^^^^^^^^^^^^^^^^^^^^^^^^^^^^^^^^^^^^^^^\n  File \"h5py/_objects.pyx\", line 54, in h5py._objects.with_phil.wrapper\n  File \"h5py/_objects.pyx\", line 55, in h5py._objects.with_phil.wrapper\n  File \"h5py/h5f.pyx\", line 122, in h5py.h5f.create\nBlockingIOError: [Errno 35] Unable to create file (unable to lock file, errno = 35, error message = 'Resource temporarily unavailable')\n"}